Workbook

Sheet README
A1: Serverless Inference Pricing Model
A2: Akamai Serverless Inference. Partner-sourced catalog, token-based pricing. Rebuilt 31 July 2026.
A4: Colour convention
A5: Blue text | B5: Hardcoded input or scenario lever. Edit these.
A6: Black text | B6: Formula computed on this tab.
A7: Green text | B7: Formula that links to another tab.
A8: Yellow fill | B8: Key assumption. Change with care, it moves every downstream number.
A10: Tabs
A11: PAYG_Model | B11: Pay as you go. Mechanics, rate build, unit economics, sample month, and its share of the launch year.
A12: Commit_Monthly | B12: Monthly commit term. Tier ladder, realized rate build, and both invoice cases, the shortfall month and the overage month.
A13: Commit_Annual | B13: Annual commit term. Tier ladder, realized rate build, and a full 12-month rolling shortfall balance worked through to term-end reconciliation.
A14: Sensitivity | B14: What the partner discount is worth and where the negotiation floors sit. Also positioning, commit adoption, volume and workload mix.
A15: Inputs | B15: Every assumption in the model sits here. Nothing else is typed anywhere else except the partner retail rates on Rate_Card.
A16: Rate_Card | B16: 26 model families. Partner retail in, list price out, through the 4-step derivation. Class rollups and the traffic-blended portfolio rate at the bottom.
A17: Plan_Economics | B17: Commit tier ladder, commitment denomination, expected tier mix, realized rate per plan, and unit economics per 1M tokens.
A18: Forecast_12M | B18: Launch year by month. Volume, plan mix ramp, revenue, gross profit, operating profit, contracted revenue.
A19: Forecast_3Y | B19: Three-year view with price deflation and fixed cost inflation.
A20: Worked_Example | B20: One model, one customer, the same consumption priced 3 ways on even and lumpy usage.
A23: How the price is derived
A24: Partner cost | B24: equals partner retail x (1 minus discount won on that model)
A25: Floor price | B25: equals partner cost / (1 minus margin floor)
A26: Ceiling price | B26: equals partner retail, which is the arbitrage limit
A27: List price | B27: equals floor plus Position_Score x (ceiling minus floor)
A28: Blended rate | B28: equals 0.60 x input plus 0.20 x cached plus 0.20 x output
A30: Provenance
A31: Rate card | B31: 26 model families, published in section 3.1 of the Inference Billing Requirements document.
A32: Partner retail | B32: Baseten and DeepInfra published prices, captured July 2026, 31 rows collapsing to 26 families. Retail on Rate_Card is stated per component at the level that reproduces the published card at the launch assumptions. Replace with the raw partner catalog when it is reloaded.
A33: Position score | B33: Class-level launch defaults standing in for the per-model derivation from 4 stored inputs. Largest accuracy gain available.
A34: Traffic share | B34: Assumption. Replace with tech preview telemetry once a full billing period is available.
A35: Discount won | B35: 45% is an assumption, not a signed term. Below 30% the method produces no valid price band.
A37: Headline recommendation on the partner discount
A38: Target | B38: 50% off partner retail. Portfolio gross margin 42.1%, worst single model 39.7%, and the deepest commit tier still clears the margin floor with 9.6 points of headroom.
A39: Accept | B39: 40%. Portfolio gross margin 35.6% and 4.7 points of headroom on the commit floor.
A40: Absolute floor | B40: 35%. Below this the deepest commit tier falls through the 15% commit margin floor and the tier ladder has to be cut short.
A41: Walk away | B41: 30%. No valid price band exists at all, because the floor price rises above the ceiling.
A42: What a point is worth | B42: About 0.69 points of portfolio margin and $5,790 of launch-year gross profit, at a cost of $11,666 of launch-year revenue.
A44: Open items
A45: Tier 1 spread | B45: Tier 1 spans 4.04x and carries 55% of traffic. Needs a split before the blended rate is quoted outside the pricing document.
A46: Provider concentration | B46: DeepInfra wins 24 of 26 families and every contested one. Re-test the dual-provider position at the next term sheet.
A47: Commit sample tiers | B47: The billing document invoice samples use $5,000 a month at 12%. That combination is not on the tier ladder.

Sheet Inputs
A1: Inputs
A2: Every blue cell is an input. Yellow fill marks the assumptions that move the most downstream.
A4: Derivation
A5: Input | B5: Value | F5: Basis
A6: Margin floor at list | B6: 0.3 | F6: Pricing policy. 30% gross margin, no exceptions at list.
A7: Negotiated wholesale discount | B7: 0.45 | F7: Assumption, not a signed term. Below 30% no valid price band exists.
A8: Workload mix, input share | B8: 0.6 | F8: Platform-level assumption. Repriced every model when it changes.
A9: Workload mix, cached share | B9: 0.2 | F9: Rises as agentic traffic grows.
A10: Workload mix, output share | B10: 0.2 | F10: The expensive component.
A11: Workload mix check, must equal 100% | B11: =B8+B9+B10 -> 1
A13: Price classes
A14: Class | B14: Upper threshold $/1M | C14: Position score | D14: Traffic share | F14: Basis
A15: Tier 1 Small | B15: 0.4 | C15: 0.4 | D15: 0.55 | F15: Position score is a class-level launch default standing in for the per-model derivation.
A16: Tier 2 Medium | B16: 1 | C16: 0.5 | D16: 0.25 | F16: Traffic share is an assumption pending tech preview telemetry.
A17: Tier 3 Large | B17: 1.6 | C17: 0.55 | D17: 0.12
A18: Tier 4 Frontier | B18: No cap | C18: 0.6 | D18: 0.08
A19: Traffic share check | B19: =SUM(D15:D18) -> 1
A21: Commit tier ladder
A22: Tier | B22: Annual commitment | C22: Monthly equivalent | D22: Monthly-term discount | E22: Annual-term discount
A23: Tier 1 | B23: 50000 | C23: =B23/12 -> 4166.6667 | D23: 0.05 | E23: 0.08
A24: Tier 2 | B24: 250000 | C24: =B24/12 -> 20833.333 | D24: 0.08 | E24: 0.11
A25: Tier 3 | B25: 1000000 | C25: =B25/12 -> 83333.333 | D25: 0.12 | E25: 0.15
A26: Tier 4 | B26: 5000000 | C26: =B26/12 -> 416666.67 | D26: 0.17 | E26: 0.2
A28: Expected tier mix, share of committed tokens
A29: Tier | B29: Monthly term | C29: Annual term
A30: Tier 1 | B30: 0.65 | C30: 0.35
A31: Tier 2 | B31: 0.27 | C31: 0.4
A32: Tier 3 | B32: 0.06 | C32: 0.22
A33: Tier 4 | B33: 0.02 | C33: 0.03
A34: Check, both columns | B34: =SUM(B30:B33) -> 1 | C34: =SUM(C30:C33) -> 1
A36: Realized rate mechanics
A37: Input | B37: Commit monthly | C37: Commit annual | F37: Basis
A38: Share of list usage inside the commitment | B38: 0.88 | C38: 1 | F38: Monthly overage is billed at full card rate. A light month is charged to the minimum and forfeited.
A39: Shortfall uplift, % of plan revenue | B39: 0.06 | C39: 0.01 | F39: The annual term has no overage rate inside the term and a shortfall rolls forward.
A41: Plan mix at month 12, share of tokens
A42: Plan | B42: Share
A43: Pay as you go | B43: 0.3 | F43: Month 1 is 100% pay as you go because nothing is contracted at launch. The mix interpolates linearly to this by month 12.
A44: Commit monthly | B44: 0.25
A45: Commit annual | B45: 0.45
A46: Check | B46: =SUM(B43:B45) -> 1
...

Sheet Rate_Card
A1: Rate Card
A2: 26 model families. Partner retail in, list price out, through the derivation on Inputs. Blue cells are partner retail, everything right of them is formula.
A3: Blended rate equals 0.60 x input plus 0.20 x cached plus 0.20 x output, at the workload mix on Inputs.
A6: Model family | B6: Source | C6: Class | D6: Position score | E6: Retail input | F6: Retail cached | G6: Retail output | H6: Cost input | I6: Cost cached | J6: Cost output | K6: Floor input | L6: Floor cached | M6: Floor output | N6: List input | O6: List cached | P6: List output | Q6: Blended list | R6: Blended cost | S6: GM at list | T6: Band exists | U6: Ceiling ok
A7: DeepSeek V4 Flash | B7: DeepInfra | C7: 1 | D7: =INDEX(Inputs!$C$15:$C$18,C7) -> 0.4 | E7: 0.089967 | F7: 0.018016 | G7: 0.180049 | H7: =E7*(1-Inputs!$B$7) -> 0.04948185 | I7: =F7*(1-Inputs!$B$7) -> 0.0099088 | J7: =G7*(1-Inputs!$B$7) -> 0.09902695 | K7: =H7/(1-Inputs!$B$6) -> 0.070688357 | L7: =I7/(1-Inputs!$B$6) -> 0.014155429 | M7: =J7/(1-Inputs!$B$6) -> 0.14146707 | N7: =K7+$D7*(E7-K7) -> 0.078399814 | O7: =L7+$D7*(F7-L7) -> 0.015699657 | P7: =M7+$D7*(G7-M7) -> 0.15689984 | Q7: =N7*Inputs!$B$8+O7*Inputs!$B$9+P7*Inputs!$B$10 -> 0.081559789 | R7: =H7*Inputs!$B$8+I7*Inputs!$B$9+J7*Inputs!$B$10 -> 0.05147626 | S7: =IF(Q7=0,0,(Q7-R7)/Q7) -> 0.36885246 | T7: =IF(Inputs!$B$7>Inputs!$B$6,"Yes","NO BAND") -> Yes | U7: =IF(Q7<=(E7*Inputs!$B$8+F7*Inputs!$B$9+G7*Inputs!$B$10)+0.000001,"Yes","BREACH") -> Yes
A8: GLM 4.7 Flash | B8: DeepInfra | C8: 1 | D8: =INDEX(Inputs!$C$15:$C$18,C8) -> 0.4 | E8: 0.060016 | F8: 0.009984 | G8: 0.400033 | H8: =E8*(1-Inputs!$B$7) -> 0.0330088 | I8: =F8*(1-Inputs!$B$7) -> 0.0054912 | J8: =G8*(1-Inputs!$B$7) -> 0.22001815 | K8: =H8/(1-Inputs!$B$6) -> 0.047155429 | L8: =I8/(1-Inputs!$B$6) -> 0.0078445714 | M8: =J8/(1-Inputs!$B$6) -> 0.31431164 | N8: =K8+$D8*(E8-K8) -> 0.052299657 | O8: =L8+$D8*(F8-L8) -> 0.0087003429 | P8: =M8+$D8*(G8-M8) -> 0.34860019 | Q8: =N8*Inputs!$B$8+O8*Inputs!$B$9+P8*Inputs!$B$10 -> 0.1028399 | R8: =H8*Inputs!$B$8+I8*Inputs!$B$9+J8*Inputs!$B$10 -> 0.06490715 | S8: =IF(Q8=0,0,(Q8-R8)/Q8) -> 0.36885246 | T8: =IF(Inputs!$B$7>Inputs!$B$6,"Yes","NO BAND") -> Yes | U8: =IF(Q8<=(E8*Inputs!$B$8+F8*Inputs!$B$9+G8*Inputs!$B$10)+0.000001,"Yes","BREACH") -> Yes
A9: Step 3.5 Flash | B9: DeepInfra | C9: 1 | D9: =INDEX(Inputs!$C$15:$C$18,C9) -> 0.4 | E9: 0.089967 | F9: 0.019967 | G9: 0.299967 | H9: =E9*(1-Inputs!$B$7) -> 0.04948185 | I9: =F9*(1-Inputs!$B$7) -> 0.01098185 | J9: =G9*(1-Inputs!$B$7) -> 0.16498185 | K9: =H9/(1-Inputs!$B$6) -> 0.070688357 | L9: =I9/(1-Inputs!$B$6) -> 0.015688357 | M9: =J9/(1-Inputs!$B$6) -> 0.23568836 | N9: =K9+$D9*(E9-K9) -> 0.078399814 | O9: =L9+$D9*(F9-L9) -> 0.017399814 | P9: =M9+$D9*(G9-M9) -> 0.26139981 | Q9: =N9*Inputs!$B$8+O9*Inputs!$B$9+P9*Inputs!$B$10 -> 0.10279981 | R9: =H9*Inputs!$B$8+I9*Inputs!$B$9+J9*Inputs!$B$10 -> 0.06488185 | S9: =IF(Q9=0,0,(Q9-R9)/Q9) -> 0.36885246 | T9: =IF(Inputs!$B$7>Inputs!$B$6,"Yes","NO BAND") -> Yes | U9: =IF(Q9<=(E9*Inputs!$B$8+F9*Inputs!$B$9+G9*Inputs!$B$10)+0.000001,"Yes","BREACH") -> Yes
A10: DeepSeek V3.2 | B10: DeepInfra | C10: 1 | D10: =INDEX(Inputs!$C$15:$C$18,C10) -> 0.4 | E10: 0.260033 | F10: 0.130016 | G10: 0.379951 | H10: =E10*(1-Inputs!$B$7) -> 0.14301815 | I10: =F10*(1-Inputs!$B$7) -> 0.0715088 | J10: =G10*(1-Inputs!$B$7) -> 0.20897305 | K10: =H10/(1-Inputs!$B$6) -> 0.20431164 | L10: =I10/(1-Inputs!$B$6) -> 0.10215543 | M10: =J10/(1-Inputs!$B$6) -> 0.29853293 | N10: =K10+$D10*(E10-K10) -> 0.22660019 | O10: =L10+$D10*(F10-L10) -> 0.11329966 | P10: =M10+$D10*(G10-M10) -> 0.33110016 | Q10: =N10*Inputs!$B$8+O10*Inputs!$B$9+P10*Inputs!$B$10 -> 0.22484007 | R10: =H10*Inputs!$B$8+I10*Inputs!$B$9+J10*Inputs!$B$10 -> 0.14190726 | S10: =IF(Q10=0,0,(Q10-R10)/Q10) -> 0.36885246 | T10: =IF(Inputs!$B$7>Inputs!$B$6,"Yes","NO BAND") -> Yes | U10: =IF(Q10<=(E10*Inputs!$B$8+F10*Inputs!$B$9+G10*Inputs!$B$10)+0.000001,"Yes","BREACH") -> Yes
A11: Qwen3 VL 235B | B11: DeepInfra | C11: 1 | D11: =INDEX(Inputs!$C$15:$C$18,C11) -> 0.4 | E11: 0.200016 | F11: 0.110049 | G11: 0.880049 | H11: =E11*(1-Inputs!$B$7) -> 0.1100088 | I11: =F11*(1-Inputs!$B$7) -> 0.06052695 | J11: =G11*(1-Inputs!$B$7) -> 0.48402695 | K11: =H11/(1-Inputs!$B$6) -> 0.15715543 | L11: =I11/(1-Inputs!$B$6) -> 0.086467071 | M11: =J11/(1-Inputs!$B$6) -> 0.69146707 | N11: =K11+$D11*(E11-K11) -> 0.17429966 | O11: =L11+$D11*(F11-L11) -> 0.095899843 | P11: =M11+$D11*(G11-M11) -> 0.76689984 | Q11: =N11*Inputs!$B$8+O11*Inputs!$B$9+P11*Inputs!$B$10 -> 0.27713973 | R11: =H11*Inputs!$B$8+I11*Inputs!$B$9+J11*Inputs!$B$10 -> 0.17491606 | S11: =IF(Q11=0,0,(Q11-R11)/Q11) -> 0.36885246 | T11: =IF(Inputs!$B$7>Inputs!$B$6,"Yes","NO BAND") -> Yes | U11: =IF(Q11<=(E11*Inputs!$B$8+F11*Inputs!$B$9+G11*Inputs!$B$10)+0.000001,"Yes","BREACH") -> Yes
A12: MiniMax M2.5 | B12: DeepInfra | C12: 1 | D12: =INDEX(Inputs!$C$15:$C$18,C12) -> 0.4 | E12: 0.149984 | F12: 0.029951 | G12: 1.149951 | H12: =E12*(1-Inputs!$B$7) -> 0.0824912 | I12: =F12*(1-Inputs!$B$7) -> 0.01647305 | J12: =G12*(1-Inputs!$B$7) -> 0.63247305 | K12: =H12/(1-Inputs!$B$6) -> 0.11784457 | L12: =I12/(1-Inputs!$B$6) -> 0.023532929 | M12: =J12/(1-Inputs!$B$6) -> 0.90353293 | N12: =K12+$D12*(E12-K12) -> 0.13070034 | O12: =L12+$D12*(F12-L12) -> 0.026100157 | P12: =M12+$D12*(G12-M12) -> 1.0021002 | Q12: =N12*Inputs!$B$8+O12*Inputs!$B$9+P12*Inputs!$B$10 -> 0.28406027 | R12: =H12*Inputs!$B$8+I12*Inputs!$B$9+J12*Inputs!$B$10 -> 0.17928394 | S12: =IF(Q12=0,0,(Q12-R12)/Q12) -> 0.36885246 | T12: =IF(Inputs!$B$7>Inputs!$B$6,"Yes","NO BAND") -> Yes | U12: =IF(Q12<=(E12*Inputs!$B$8+F12*Inputs!$B$9+G12*Inputs!$B$10)+0.000001,"Yes","BREACH") -> Yes
A13: DeepSeek V3.1 Terminus | B13: DeepInfra | C13: 1 | D13: =INDEX(Inputs!$C$15:$C$18,C13) -> 0.4 | E13: 0.270016 | F13: 0.130016 | G13: 0.950049 | H13: =E13*(1-Inputs!$B$7) -> 0.1485088 | I13: =F13*(1-Inputs!$B$7) -> 0.0715088 | J13: =G13*(1-Inputs!$B$7) -> 0.52252695 | K13: =H13/(1-Inputs!$B$6) -> 0.21215543 | L13: =I13/(1-Inputs!$B$6) -> 0.10215543 | M13: =J13/(1-Inputs!$B$6) -> 0.74646707 | N13: =K13+$D13*(E13-K13) -> 0.23529966 | O13: =L13+$D13*(F13-L13) -> 0.11329966 | P13: =M13+$D13*(G13-M13) -> 0.82789984 | Q13: =N13*Inputs!$B$8+O13*Inputs!$B$9+P13*Inputs!$B$10 -> 0.32941969 | R13: =H13*Inputs!$B$8+I13*Inputs!$B$9+J13*Inputs!$B$10 -> 0.20791243 | S13: =IF(Q13=0,0,(Q13-R13)/Q13) -> 0.36885246 | T13: =IF(Inputs!$B$7>Inputs!$B$6,"Yes","NO BAND") -> Yes | U13: =IF(Q13<=(E13*Inputs!$B$8+F13*Inputs!$B$9+G13*Inputs!$B$10)+0.000001,"Yes","BREACH") -> Yes
A14: Qwen3 Coder 480B Turbo | B14: DeepInfra | C14: 2 | D14: =INDEX(Inputs!$C$15:$C$18,C14) -> 0.5 | E14: 0.300048 | F14: 0.100016 | G14: 1.000048 | H14: =E14*(1-Inputs!$B$7) -> 0.1650264 | I14: =F14*(1-Inputs!$B$7) -> 0.0550088 | J14: =G14*(1-Inputs!$B$7) -> 0.5500264 | K14: =H14/(1-Inputs!$B$6) -> 0.235752 | L14: =I14/(1-Inputs!$B$6) -> 0.078584 | M14: =J14/(1-Inputs!$B$6) -> 0.785752 | N14: =K14+$D14*(E14-K14) -> 0.2679 | O14: =L14+$D14*(F14-L14) -> 0.0893 | P14: =M14+$D14*(G14-M14) -> 0.8929 | Q14: =N14*Inputs!$B$8+O14*Inputs!$B$9+P14*Inputs!$B$10 -> 0.35718 | R14: =H14*Inputs!$B$8+I14*Inputs!$B$9+J14*Inputs!$B$10 -> 0.22002288 | S14: =IF(Q14=0,0,(Q14-R14)/Q14) -> 0.384 | T14: =IF(Inputs!$B$7>Inputs!$B$6,"Yes","NO BAND") -> Yes | U14: =IF(Q14<=(E14*Inputs!$B$8+F14*Inputs!$B$9+G14*Inputs!$B$10)+0.000001,"Yes","BREACH") -> Yes
A15: Qwen3 235B Thinking 2507 | B15: DeepInfra | C15: 2 | D15: =INDEX(Inputs!$C$15:$C$18,C15) -> 0.5 | E15: 0.230048 | F15: 0.200032 | G15: 2.300032 | H15: =E15*(1-Inputs!$B$7) -> 0.1265264 | I15: =F15*(1-Inputs!$B$7) -> 0.1100176 | J15: =G15*(1-Inputs!$B$7) -> 1.2650176 | K15: =H15/(1-Inputs!$B$6) -> 0.180752 | L15: =I15/(1-Inputs!$B$6) -> 0.157168 | M15: =J15/(1-Inputs!$B$6) -> 1.807168 | N15: =K15+$D15*(E15-K15) -> 0.2054 | O15: =L15+$D15*(F15-L15) -> 0.1786 | P15: =M15+$D15*(G15-M15) -> 2.0536 | Q15: =N15*Inputs!$B$8+O15*Inputs!$B$9+P15*Inputs!$B$10 -> 0.56968 | R15: =H15*Inputs!$B$8+I15*Inputs!$B$9+J15*Inputs!$B$10 -> 0.35092288 | S15: =IF(Q15=0,0,(Q15-R15)/Q15) -> 0.384 | T15: =IF(Inputs!$B$7>Inputs!$B$6,"Yes","NO BAND") -> Yes | U15: =IF(Q15<=(E15*Inputs!$B$8+F15*Inputs!$B$9+G15*Inputs!$B$10)+0.000001,"Yes","BREACH") -> Yes
A16: MiMo v2.5 | B16: DeepInfra | C16: 2 | D16: =INDEX(Inputs!$C$15:$C$18,C16) -> 0.5 | E16: 0.399952 | F16: 0.079968 | G16: 1.999984 | H16: =E16*(1-Inputs!$B$7) -> 0.2199736 | I16: =F16*(1-Inputs!$B$7) -> 0.0439824 | J16: =G16*(1-Inputs!$B$7) -> 1.0999912 | K16: =H16/(1-Inputs!$B$6) -> 0.314248 | L16: =I16/(1-Inputs!$B$6) -> 0.062832 | M16: =J16/(1-Inputs!$B$6) -> 1.571416 | N16: =K16+$D16*(E16-K16) -> 0.3571 | O16: =L16+$D16*(F16-L16) -> 0.0714 | P16: =M16+$D16*(G16-M16) -> 1.7857 | Q16: =N16*Inputs!$B$8+O16*Inputs!$B$9+P16*Inputs!$B$10 -> 0.58568 | R16: =H16*Inputs!$B$8+I16*Inputs!$B$9+J16*Inputs!$B$10 -> 0.36077888 | S16: =IF(Q16=0,0,(Q16-R16)/Q16) -> 0.384 | T16: =IF(Inputs!$B$7>Inputs!$B$6,"Yes","NO BAND") -> Yes | U16: =IF(Q16<=(E16*Inputs!$B$8+F16*Inputs!$B$9+G16*Inputs!$B$10)+0.000001,"Yes","BREACH") -> Yes
A17: Kimi K2.5 | B17: DeepInfra | C17: 2 | D17: =INDEX(Inputs!$C$15:$C$18,C17) -> 0.5 | E17: 0.450016 | F17: 0.07 | G17: 2.249968 | H17: =E17*(1-Inputs!$B$7) -> 0.2475088 | I17: =F17*(1-Inputs!$B$7) -> 0.0385 | J17: =G17*(1-Inputs!$B$7) -> 1.2374824 | K17: =H17/(1-Inputs!$B$6) -> 0.353584 | L17: =I17/(1-Inputs!$B$6) -> 0.055 | M17: =J17/(1-Inputs!$B$6) -> 1.767832 | N17: =K17+$D17*(E17-K17) -> 0.4018 | O17: =L17+$D17*(F17-L17) -> 0.0625 | P17: =M17+$D17*(G17-M17) -> 2.0089 | Q17: =N17*Inputs!$B$8+O17*Inputs!$B$9+P17*Inputs!$B$10 -> 0.65536 | R17: =H17*Inputs!$B$8+I17*Inputs!$B$9+J17*Inputs!$B$10 -> 0.40370176 | S17: =IF(Q17=0,0,(Q17-R17)/Q17) -> 0.384 | T17: =IF(Inputs!$B$7>Inputs!$B$6,"Yes","NO BAND") -> Yes | U17: =IF(Q17<=(E17*Inputs!$B$8+F17*Inputs!$B$9+G17*Inputs!$B$10)+0.000001,"Yes","BREACH") -> Yes
A18: Nemotron 3 Ultra | B18: DeepInfra | C18: 2 | D18: =INDEX(Inputs!$C$15:$C$18,C18) -> 0.5 | E18: 0.499968 | F18: 0.100016 | G18: 2.200016 | H18: =E18*(1-Inputs!$B$7) -> 0.2749824 | I18: =F18*(1-Inputs!$B$7) -> 0.0550088 | J18: =G18*(1-Inputs!$B$7) -> 1.2100088 | K18: =H18/(1-Inputs!$B$6) -> 0.392832 | L18: =I18/(1-Inputs!$B$6) -> 0.078584 | M18: =J18/(1-Inputs!$B$6) -> 1.728584 | N18: =K18+$D18*(E18-K18) -> 0.4464 | O18: =L18+$D18*(F18-L18) -> 0.0893 | P18: =M18+$D18*(G18-M18) -> 1.9643 | Q18: =N18*Inputs!$B$8+O18*Inputs!$B$9+P18*Inputs!$B$10 -> 0.67856 | R18: =H18*Inputs!$B$8+I18*Inputs!$B$9+J18*Inputs!$B$10 -> 0.41799296 | S18: =IF(Q18=0,0,(Q18-R18)/Q18) -> 0.384 | T18: =IF(Inputs!$B$7>Inputs!$B$6,"Yes","NO BAND") -> Yes | U18: =IF(Q18<=(E18*Inputs!$B$8+F18*Inputs!$B$9+G18*Inputs!$B$10)+0.000001,"Yes","BREACH") -> Yes
... A32: Qwen3.7 Max | B32: DeepInfra | C32: 4 | D32: =INDEX(Inputs!$C$15:$C$18,C32) -> 0.6 | E32: 2.499984 | F32: 0.499953 | G32: 7.499953 | H32: =E32*(1-Inputs!$B$7) -> 1.3749912 | I32: =F32*(1-Inputs!$B$7) -> 0.27497415 | J32: =G32*(1-Inputs!$B$7) -> 4.1249741 | K32: =H32/(1-Inputs!$B$6) -> 1.9642731 | L32: =I32/(1-Inputs!$B$6) -> 0.39282021 | M32: =J32/(1-Inputs!$B$6) -> 5.8928202 | N32: =K32+$D32*(E32-K32) -> 2.2856997 | O32: =L32+$D32*(F32-L32) -> 0.45709989 | P32: =M32+$D32*(G32-M32) -> 6.8570999 | Q32: =N32*Inputs!$B$8+O32*Inputs!$B$9+P32*Inputs!$B$10 -> 2.8342597 | R32: =H32*Inputs!$B$8+I32*Inputs!$B$9+J32*Inputs!$B$10 -> 1.7049844 | S32: =IF(Q32=0,0,(Q32-R32)/Q32) -> 0.3984375 | T32: =IF(Inputs!$B$7>Inputs!$B$6,"Yes","NO BAND") -> Yes | U32: =IF(Q32<=(E32*Inputs!$B$8+F32*Inputs!$B$9+G32*Inputs!$B$10)+0.000001,"Yes","BREACH") -> Yes
A34: Class rollup
A35: Class | B35: Models | C35: Avg list $/1M | D35: Avg wholesale $/1M | E35: GM at list | F35: Min list | G35: Max list | H35: Within-class spread | I35: Traffic share | J35: Revenue share | K35: Avg retail $/1M | L35: Position score | M35: Avg list in | N35: Avg list cached | O35: Avg list out | P35: Avg cost in | Q35: Avg cost cached | R35: Avg cost out
A36: Tier 1 Small | B36: =COUNTIF($C$7:$C$32,1) -> 7 | C36: =SUMIF($C$7:$C$32,1,$Q$7:$Q$32)/B36 -> 0.2003799 | D36: =SUMIF($C$7:$C$32,1,$R$7:$R$32)/B36 -> 0.12646928 | E36: =(C36-D36)/C36 -> 0.36885246 | F36: =_xlfn.MINIFS($Q$7:$Q$32,$C$7:$C$32,1) -> 0.081559789 | G36: =_xlfn.MAXIFS($Q$7:$Q$32,$C$7:$C$32,1) -> 0.32941969 | H36: =G36/F36 -> 4.0389964 | I36: =Inputs!D15 -> 0.55 | J36: =I36*C36/SUMPRODUCT($I$36:$I$39,$C$36:$C$39) -> 0.18942084 | K36: =D36/(1-Inputs!$B$7) -> 0.22994414 | L36: =Inputs!C15 -> 0.4 | M36: =SUMIF($C$7:$C$32,1,$N$7:$N$32)/B36 -> 0.13942845 | N36: =SUMIF($C$7:$C$32,1,$O$7:$O$32)/B36 -> 0.055771304 | O36: =SUMIF($C$7:$C$32,1,$P$7:$P$32)/B36 -> 0.52784283 | P36: =SUMIF($C$7:$C$32,1,$H$7:$H$32)/B36 -> 0.087999921 | Q36: =SUMIF($C$7:$C$32,1,$I$7:$I$32)/B36 -> 0.035199921 | R36: =SUMIF($C$7:$C$32,1,$J$7:$J$32)/B36 -> 0.33314671
A37: Tier 2 Medium | B37: =COUNTIF($C$7:$C$32,2) -> 9 | C37: =SUMIF($C$7:$C$32,2,$Q$7:$Q$32)/B37 -> 0.64741778 | D37: =SUMIF($C$7:$C$32,2,$R$7:$R$32)/B37 -> 0.39880935 | E37: =(C37-D37)/C37 -> 0.384 | F37: =_xlfn.MINIFS($Q$7:$Q$32,$C$7:$C$32,2) -> 0.35718 | G37: =_xlfn.MAXIFS($Q$7:$Q$32,$C$7:$C$32,2) -> 0.81608 | H37: =G37/F37 -> 2.2847864 | I37: =Inputs!D16 -> 0.25 | J37: =I37*C37/SUMPRODUCT($I$36:$I$39,$C$36:$C$39) -> 0.27818619 | K37: =D37/(1-Inputs!$B$7) -> 0.72510791 | L37: =Inputs!C16 -> 0.5 | M37: =SUMIF($C$7:$C$32,2,$N$7:$N$32)/B37 -> 0.3998 | N37: =SUMIF($C$7:$C$32,2,$O$7:$O$32)/B37 -> 0.13491111 | O37: =SUMIF($C$7:$C$32,2,$P$7:$P$32)/B37 -> 1.9027778 | P37: =SUMIF($C$7:$C$32,2,$H$7:$H$32)/B37 -> 0.2462768 | Q37: =SUMIF($C$7:$C$32,2,$I$7:$I$32)/B37 -> 0.083105244 | R37: =SUMIF($C$7:$C$32,2,$J$7:$J$32)/B37 -> 1.1721111
A38: Tier 3 Large | B38: =COUNTIF($C$7:$C$32,3) -> 7 | C38: =SUMIF($C$7:$C$32,3,$Q$7:$Q$32)/B38 -> 1.1517943 | D38: =SUMIF($C$7:$C$32,3,$R$7:$R$32)/B38 -> 0.70109221 | E38: =(C38-D38)/C38 -> 0.39130435 | F38: =_xlfn.MINIFS($Q$7:$Q$32,$C$7:$C$32,3) -> 1.0607601 | G38: =_xlfn.MAXIFS($Q$7:$Q$32,$C$7:$C$32,3) -> 1.3047803 | H38: =G38/F38 -> 1.2300427 | I38: =Inputs!D17 -> 0.12 | J38: =I38*C38/SUMPRODUCT($I$36:$I$39,$C$36:$C$39) -> 0.23755661 | K38: =D38/(1-Inputs!$B$7) -> 1.2747131 | L38: =Inputs!C17 -> 0.55 | M38: =SUMIF($C$7:$C$32,3,$N$7:$N$32)/B38 -> 0.87388588 | N38: =SUMIF($C$7:$C$32,3,$O$7:$O$32)/B38 -> 0.14907121 | O38: =SUMIF($C$7:$C$32,3,$P$7:$P$32)/B38 -> 2.9882429 | P38: =SUMIF($C$7:$C$32,3,$H$7:$H$32)/B38 -> 0.53193054 | Q38: =SUMIF($C$7:$C$32,3,$I$7:$I$32)/B38 -> 0.090739 | R38: =SUMIF($C$7:$C$32,3,$J$7:$J$32)/B38 -> 1.8189305
A39: Tier 4 Frontier | B39: =COUNTIF($C$7:$C$32,4) -> 3 | C39: =SUMIF($C$7:$C$32,4,$Q$7:$Q$32)/B39 -> 2.1442732 | D39: =SUMIF($C$7:$C$32,4,$R$7:$R$32)/B39 -> 1.2899143 | E39: =(C39-D39)/C39 -> 0.3984375 | F39: =_xlfn.MINIFS($Q$7:$Q$32,$C$7:$C$32,4) -> 1.7992799 | G39: =_xlfn.MAXIFS($Q$7:$Q$32,$C$7:$C$32,4) -> 2.8342597 | H39: =G39/F39 -> 1.5752189 | I39: =Inputs!D18 -> 0.08 | J39: =I39*C39/SUMPRODUCT($I$36:$I$39,$C$36:$C$39) -> 0.29483636 | K39: =D39/(1-Inputs!$B$7) -> 2.3452988 | L39: =Inputs!C18 -> 0.6 | M39: =SUMIF($C$7:$C$32,4,$N$7:$N$32)/B39 -> 1.4932998 | N39: =SUMIF($C$7:$C$32,4,$O$7:$O$32)/B39 -> 0.29863345 | O39: =SUMIF($C$7:$C$32,4,$P$7:$P$32)/B39 -> 5.9428331 | P39: =SUMIF($C$7:$C$32,4,$H$7:$H$32)/B39 -> 0.89831317 | Q39: =SUMIF($C$7:$C$32,4,$I$7:$I$32)/B39 -> 0.17964668 | R39: =SUMIF($C$7:$C$32,4,$J$7:$J$32)/B39 -> 3.5749855
A41: Portfolio, traffic-blended
A42: Card rate $/1M tokens | B42: =SUMPRODUCT($I$36:$I$39,$C$36:$C$39) -> 0.58182056 | D42: This is the number the forecast and plan economics run on.
A43: Wholesale cost $/1M tokens | B43: =SUMPRODUCT($I$36:$I$39,$D$36:$D$39) -> 0.35658465
A44: Gross profit $/1M tokens | B44: =B42-B43 -> 0.22523591
A45: Gross margin at list | B45: =B44/B42 -> 0.38712264
A46: Worst single model GM | B46: =MIN($S$7:$S$32) -> 0.36885246 | D46: Tested against the commit floor guard on Plan_Economics.
A48: Note. Retail is stated per component at the level that reproduces the published card at the launch assumptions. When the raw partner catalog is reloaded, overwrite columns E to G with published partner retail and the list prices will re-derive.

Sheet PAYG_Model
A1: Pay As You Go
A2: The default plan. Metered consumption at the published card rate, no minimum, no term, no negotiation.
A4: Mechanics
A5: Rate applied | E5: Published card rate for the model and token component. No customer-specific card.
A6: Minimum spend | E6: None. A month with no traffic produces no invoice.
A7: Term | E7: None. The customer can stop at any time.
A8: Rate changes | E8: A published card change takes effect on the next billing period. There is no rate lock.
A9: Invoice | E9: Sum over every model and component of tokens x the rate quoted from the card.
A10: Why it exists | E10: It is the on-ramp. Every customer starts here, and it sets the reference price that both commit plans discount from.
A12: Rate and unit economics per 1M tokens
A13: Metric | B13: Value | E13: Note
A14: Card rate, traffic-blended | B14: =Rate_Card!$B$42 -> 0.58182056 | E14: Portfolio blend across the 4 price classes at the traffic shares on Inputs.
A15: Effective multiplier vs card | B15: =Plan_Economics!$C$27 -> 1 | E15: There is no discount, no minimum and no shortfall, so the multiplier is exactly 1.
A16: Realized rate | B16: =B14*B15 -> 0.58182056
A17: Wholesale cost | B17: =Rate_Card!$B$43 -> 0.35658465 | E17: Identical on all 3 plans. The partner is paid per token whatever the customer contract says.
A18: Gross profit | B18: =B16-B17 -> 0.22523591
A19: Gross margin | B19: =B18/B16 -> 0.38712264 | E19: The highest of the 3 plans, by construction.
A21: Sample month
A22: Line | B22: Volume 1M tokens | C22: Rate $/1M | D22: Amount
A23: Metered consumption | B23: 110000 | C23: =$B$16 -> 0.58182056 | D23: =B23*C23 -> 64000.262 | E23: Blue cell. Change the volume to reprice the month.
A24: Discount applied | D24: 0
A25: Invoice total | D25: =D23-D24 -> 64000.262
A26: Wholesale cost of that month | D26: =B23*$B$17 -> 39224.312
A27: Gross profit | D27: =D25-D26 -> 24775.95
A29: Contribution to the launch year
A30: Metric | B30: Value
A31: Share of tokens at month 12 | B31: =Inputs!$B$43 -> 0.3 | E31: Pay as you go carries the whole book at launch and falls to under a third by month 12 as commit deals close.
A32: Share of tokens at month 1 | B32: =Forecast_12M!$B$7 -> 1
A33: Revenue across the launch year | B33: =SUMPRODUCT(Forecast_12M!$B$5:$M$5,Forecast_12M!$B$7:$M$7)*$B$16 -> 1021074.7
A34: Share of launch-year revenue | B34: =B33/Forecast_12M!$N$11 -> 0.66709243

Sheet Commit_Monthly
A1: Commit, Monthly Term
A2: A minimum monthly spend in exchange for a discounted rate card. Each month settles on its own.
A4: Mechanics
A5: Commitment | F5: A monetary minimum per month, stated in discounted dollars.
A6: Rate applied | F6: A customer-specific card at the tier discount off list, on usage up to the commitment.
A7: Above the commitment | F7: Overage is billed at the full published card rate, not the discounted rate.
A8: Below the commitment | F8: The invoice is the minimum. The shortfall is charged that same month.
A9: Carryover | F9: None. A light month is forfeited and does not reduce a later month.
A10: Invoice | F10: Greater of the contractual minimum or actual rated usage.
A12: Tier ladder
A13: Tier | B13: Annual commitment | C13: Monthly minimum | D13: Discount | E13: List usage that fills the minimum | F13: Expected share of committed tokens
A14: Tier 1 | B14: =Inputs!B23 -> 50000 | C14: =Inputs!C23 -> 4166.6667 | D14: =Inputs!D23 -> 0.05 | E14: =C14/(1-D14) -> 4385.9649 | F14: =Inputs!B30 -> 0.65
A15: Tier 2 | B15: =Inputs!B24 -> 250000 | C15: =Inputs!C24 -> 20833.333 | D15: =Inputs!D24 -> 0.08 | E15: =C15/(1-D15) -> 22644.928 | F15: =Inputs!B31 -> 0.27
A16: Tier 3 | B16: =Inputs!B25 -> 1000000 | C16: =Inputs!C25 -> 83333.333 | D16: =Inputs!D25 -> 0.12 | E16: =C16/(1-D16) -> 94696.97 | F16: =Inputs!B32 -> 0.06
A17: Tier 4 | B17: =Inputs!B26 -> 5000000 | C17: =Inputs!C26 -> 416666.67 | D17: =Inputs!D26 -> 0.17 | E17: =C17/(1-D17) -> 502008.03 | F17: =Inputs!B33 -> 0.02
A18: Weighted discount | D18: =SUMPRODUCT(D14:D17,F14:F17) -> 0.0647
F19: A commitment is stated in discounted dollars, so the list usage needed to reach it is always larger than the commitment itself.
A21: Realized rate
A22: Component | B22: Value | F22: Note
A23: Weighted discount off card rate | B23: =D18 -> 0.0647 | F23: From the tier ladder above.
A24: Share of list usage inside the commitment | B24: =Inputs!$B$38 -> 0.88 | F24: The rest is overage at full card rate.
A25: Share billed at full card rate | B25: =1-B24 -> 0.12
A26: Shortfall uplift, % of plan revenue | B26: =Inputs!$B$39 -> 0.06 | F26: Revenue collected above consumption when a customer bills to the minimum in a light month.
A27: Effective multiplier vs card rate | B27: =(B24*(1-B23)+B25)*(1+B26) -> 0.99964784 | F27: Lands on top of pay as you go. The stated discount is almost entirely given back through overage and forfeits.
A28: Realized rate $/1M | B28: =Rate_Card!$B$42*B27 -> 0.58161567
A29: Wholesale cost $/1M | B29: =Rate_Card!$B$43 -> 0.35658465
A30: Gross profit $/1M | B30: =B28-B29 -> 0.22503102
A31: Gross margin | B31: =B30/B28 -> 0.38690673
A32: Points given up vs pay as you go | B32: =(PAYG_Model!$B$19-B31)*100 -> 0.021590693 | F32: Close to zero. This plan is nearly free to offer.
A34: Sample invoices, Tier 2
A35: Monthly minimum and discount are pulled from the ladder. Change the usage cell to switch between the two cases.
A36: Line | B36: Shortfall month | C36: Overage month
A37: List usage in the month | B37: 150000 | C37: 260000
A38: Monthly minimum | B38: =$C$15 -> 20833.333 | C38: =$C$15 -> 20833.333
A39: List usage that fills the minimum | B39: =$E$15 -> 22644.928 | C39: =$E$15 -> 22644.928
A40: Usage inside the commitment, at list | B40: =MIN(B37,B39) -> 22644.928 | C40: =MIN(C37,C39) -> 22644.928
A41: Discount on that usage | B41: =-B40*$D$15 -> -1811.5942 | C41: =-C40*$D$15 -> -1811.5942
A42: Overage, at full card rate | B42: =MAX(0,B37-B39) -> 127355.07 | C42: =MAX(0,C37-C39) -> 237355.07
A43: Rated usage total | B43: =B40+B41+B42 -> 148188.41 | C43: =C40+C41+C42 -> 258188.41
A44: Shortfall to the minimum | B44: =MAX(0,B38-B43) -> 0 | C44: =MAX(0,C38-C43) -> 0
...

Sheet Commit_Annual
A1: Commit, Annual Term
A2: A minimum spend across a 12-month term. Shortfalls roll month to month as a running balance and reconcile once at term end.
A4: Mechanics
A5: Commitment | H5: A monetary minimum for the full term, spread pro-rata across 12 months to set a monthly minimum.
A6: Rate applied | H6: A customer-specific card at the tier discount, locked for the term.
A7: Above the minimum | H7: No separate overage rate. All in-term usage is billed at the locked discounted rate.
A8: Below the minimum | H8: The month is invoiced at actual usage. The gap adds to a rolling shortfall balance carried as a memo, not charged.
A9: Rolling balance | H9: Equals the greater of zero and the pro-rata minimum owed to date less cumulative usage to date. A heavy month draws it back down.
A10: Term end | H10: The remaining balance is reconciled once, on the final invoice.
A11: Why a customer moves here | H11: A deeper discount at every tier, shortfall rollover instead of forfeit, and a rate lock. The trade is a 12-month commitment.
A13: Tier ladder
A14: Tier | B14: Annual commitment | C14: Pro-rata monthly minimum | D14: Discount | E14: List usage that fills the term | F14: Expected share of committed tokens | G14: Extra points vs monthly term
A15: Tier 1 | B15: =Inputs!B23 -> 50000 | C15: =B15/12 -> 4166.6667 | D15: =Inputs!E23 -> 0.08 | E15: =B15/(1-D15) -> 54347.826 | F15: =Inputs!C30 -> 0.35 | G15: =(Inputs!E23-Inputs!D23)*100 -> 3
A16: Tier 2 | B16: =Inputs!B24 -> 250000 | C16: =B16/12 -> 20833.333 | D16: =Inputs!E24 -> 0.11 | E16: =B16/(1-D16) -> 280898.88 | F16: =Inputs!C31 -> 0.4 | G16: =(Inputs!E24-Inputs!D24)*100 -> 3
A17: Tier 3 | B17: =Inputs!B25 -> 1000000 | C17: =B17/12 -> 83333.333 | D17: =Inputs!E25 -> 0.15 | E17: =B17/(1-D17) -> 1176470.6 | F17: =Inputs!C32 -> 0.22 | G17: =(Inputs!E25-Inputs!D25)*100 -> 3
A18: Tier 4 | B18: =Inputs!B26 -> 5000000 | C18: =B18/12 -> 416666.67 | D18: =Inputs!E26 -> 0.2 | E18: =B18/(1-D18) -> 6250000 | F18: =Inputs!C33 -> 0.03 | G18: =(Inputs!E26-Inputs!D26)*100 -> 3
A19: Weighted discount | D19: =SUMPRODUCT(D15:D18,F15:F18) -> 0.111
A21: Realized rate
A22: Component | B22: Value | H22: Note
A23: Weighted discount off card rate | B23: =D19 -> 0.111 | H23: Deeper than the monthly ladder at every tier.
A24: Share of list usage inside the commitment | B24: =Inputs!$C$38 -> 1 | H24: All in-term usage prices at the locked rate, so this is 100%.
A25: Share billed at full card rate | B25: =1-B24 -> 0 | H25: No overage rate inside the term.
A26: Shortfall uplift, % of plan revenue | B26: =Inputs!$C$39 -> 0.01 | H26: Small. A shortfall rolls forward rather than being charged, so it is only collected at term end.
A27: Effective multiplier vs card rate | B27: =(B24*(1-B23)+B25)*(1+B26) -> 0.89789 | H27: This is the only plan that trades real margin.
A28: Realized rate $/1M | B28: =Rate_Card!$B$42*B27 -> 0.52241087
A29: Wholesale cost $/1M | B29: =Rate_Card!$B$43 -> 0.35658465
A30: Gross profit $/1M | B30: =B28-B29 -> 0.16582621
A31: Gross margin | B31: =B30/B28 -> 0.31742489
A32: Points given up vs pay as you go | B32: =(PAYG_Model!$B$19-B31)*100 -> 6.9697744 | H32: The price of contracted revenue and a longer relationship.
A34: Rolling balance, Tier 2 worked term
A35: Blue cells are monthly list usage. The balance is a memo on the invoice, never charged until term end.
A36: Annual commitment | B36: =$B$16 -> 250000
A37: Pro-rata monthly minimum | B37: =$C$16 -> 20833.333
A38: Locked discount | B38: =$D$16 -> 0.11
A40: Month | B40: 1 | C40: 2 | D40: 3 | E40: 4 | F40: 5 | G40: 6 | H40: 7 | I40: 8 | J40: 9 | K40: 10 | L40: 11 | M40: 12 | N40: Term total
A41: List usage in the month | B41: 55000 | C41: 60000 | D41: 70000 | E41: 80000 | F41: 95000 | G41: 110000 | H41: 130000 | I41: 150000 | J41: 175000 | K41: 195000 | L41: 210000 | M41: 230000 | N41: =SUM(B41:M41) -> 1560000
A42: Invoice, usage at the locked rate | B42: =B41*(1-$B$38) -> 48950 | C42: =C41*(1-$B$38) -> 53400 | D42: =D41*(1-$B$38) -> 62300 | E42: =E41*(1-$B$38) -> 71200 | F42: =F41*(1-$B$38) -> 84550 | G42: =G41*(1-$B$38) -> 97900 | H42: =H41*(1-$B$38) -> 115700 | I42: =I41*(1-$B$38) -> 133500 | ... M42: =M41*(1-$B$38) -> 204700 | N42: =SUM(B42:M42) -> 1388400
A43: Cumulative invoiced | B43: =B42 -> 48950 | C43: =B43+C42 -> 102350 | D43: =C43+D42 -> 164650 | E43: =D43+E42 -> 235850 | F43: =E43+F42 -> 320400 | G43: =F43+G42 -> 418300 | H43: =G43+H42 -> 534000 | I43: =H43+I42 -> 667500 | J43: =I43+J42 -> 823250 | ... M43: =L43+M42 -> 1388400
A44: Cumulative minimum owed to date | B44: =$B$37*1 -> 20833.333 | C44: =$B$37*2 -> 41666.667 | D44: =$B$37*3 -> 62500 | E44: =$B$37*4 -> 83333.333 | F44: =$B$37*5 -> 104166.67 | G44: =$B$37*6 -> 125000 | H44: =$B$37*7 -> 145833.33 | I44: =$B$37*8 -> 166666.67 | J44: =$B$37*9 -> 187500 | K44: =$B$37*10 -> 208333.33 | L44: =$B$37*11 -> 229166.67 | M44: =$B$37*12 -> 250000
A45: Rolling shortfall balance, memo only | B45: =MAX(0,B44-B43) -> 0 | C45: =MAX(0,C44-C43) -> 0 | D45: =MAX(0,D44-D43) -> 0 | E45: =MAX(0,E44-E43) -> 0 | F45: =MAX(0,F44-F43) -> 0 | G45: =MAX(0,G44-G43) -> 0 | H45: =MAX(0,H44-H43) -> 0 | I45: =MAX(0,I44-I43) -> 0 | ... M45: =MAX(0,M44-M43) -> 0
...

Sheet Plan_Economics
A1: Plan Economics
A2: Two plans ship in v1, pay as you go and commit. Commit is minimum-spend with true-up, sold on a monthly or annual term.
A4: Commitment denomination
A5: A commitment is stated in discounted dollars. The list usage required to reach it is larger than the commitment itself.
A6: List usage to reach a commitment equals commitment / (1 minus discount).
A7: Tier | B7: Annual commitment | C7: List usage to reach it | D7: Monthly minimum | E7: List usage to reach it
A8: Tier 1 | B8: =Inputs!B23 -> 50000 | C8: =B8/(1-Inputs!E23) -> 54347.826 | D8: =Inputs!C23 -> 4166.6667 | E8: =D8/(1-Inputs!D23) -> 4385.9649
A9: Tier 2 | B9: =Inputs!B24 -> 250000 | C9: =B9/(1-Inputs!E24) -> 280898.88 | D9: =Inputs!C24 -> 20833.333 | E9: =D9/(1-Inputs!D24) -> 22644.928
A10: Tier 3 | B10: =Inputs!B25 -> 1000000 | C10: =B10/(1-Inputs!E25) -> 1176470.6 | D10: =Inputs!C25 -> 83333.333 | E10: =D10/(1-Inputs!D25) -> 94696.97
A11: Tier 4 | B11: =Inputs!B26 -> 5000000 | C11: =B11/(1-Inputs!E26) -> 6250000 | D11: =Inputs!C26 -> 416666.67 | E11: =D11/(1-Inputs!D26) -> 502008.03
A13: Weighted discount by term
A14: The discount actually given up is the tier discount weighted by where committed tokens land.
A15: Term | B15: Weighted discount
A16: Commit monthly | B16: =SUMPRODUCT(Inputs!B30:B33,Inputs!D23:D26) -> 0.0647
A17: Commit annual | B17: =SUMPRODUCT(Inputs!C30:C33,Inputs!E23:E26) -> 0.111
A18: Annual gives up more | B18: =B17-B16 -> 0.0463
A20: Realized rate
A21: Effective multiplier equals (share inside the commitment x (1 minus discount) plus overage share) x (1 plus shortfall uplift).
A22: Input | B22: Pay as you go | C22: Commit monthly | D22: Commit annual
A23: Weighted discount off card rate | C23: 0 | D23: =B16 -> 0.0647 | E23: =B17 -> 0.111
A24: Share of list usage inside the commitment | C24: 1 | D24: =Inputs!B38 -> 0.88 | E24: =Inputs!C38 -> 1
A25: Share billed at full card rate | C25: =1-C24 -> 0 | D25: =1-D24 -> 0.12 | E25: =1-E24 -> 0
A26: Shortfall uplift, % of plan revenue | C26: 0 | D26: =Inputs!B39 -> 0.06 | E26: =Inputs!C39 -> 0.01
A27: Effective multiplier vs card rate | C27: =(C24*(1-C23)+C25)*(1+C26) -> 1 | D27: =(D24*(1-D23)+D25)*(1+D26) -> 0.99964784 | E27: =(E24*(1-E23)+E25)*(1+E26) -> 0.89789 | F27: The monthly term lands on top of pay as you go once overage and forfeits are counted, so it costs close to nothing in margin to offer. Only the annual term trades real margin.
A29: Unit economics per 1M tokens
A30: Wholesale cost is identical on all 3 plans. The partner is paid per token whatever the customer contract says.
A31: Metric | C31: Pay as you go | D31: Commit monthly | E31: Commit annual | F31: Blended
A32: Token share at month 12 | C32: =Inputs!B43 -> 0.3 | D32: =Inputs!B44 -> 0.25 | E32: =Inputs!B45 -> 0.45 | F32: =SUM(C32:E32) -> 1
A33: Realized rate $/1M | C33: =Rate_Card!$B$42*C27 -> 0.58182056 | D33: =Rate_Card!$B$42*D27 -> 0.58161567 | E33: =Rate_Card!$B$42*E27 -> 0.52241087 | F33: =SUMPRODUCT($C$32:$E$32,$C$33:$E$33) -> 0.55503498
A34: Wholesale cost $/1M | C34: =Rate_Card!$B$43 -> 0.35658465 | D34: =Rate_Card!$B$43 -> 0.35658465 | E34: =Rate_Card!$B$43 -> 0.35658465 | F34: =Rate_Card!$B$43 -> 0.35658465
A35: Gross profit $/1M | C35: =C33-C34 -> 0.22523591 | D35: =D33-D34 -> 0.22503102 | E35: =E33-E34 -> 0.16582621 | F35: =F33-F34 -> 0.19845032
A36: Gross margin % | C36: =C35/C33 -> 0.38712264 | D36: =D35/D33 -> 0.38690673 | E36: =E35/E33 -> 0.31742489
A37: Points given up vs pay as you go | C37: =($C$36-C36)*100 -> 0 | D37: =($C$36-D36)*100 -> 0.021590693 | E37: =($C$36-E36)*100 -> 6.9697744 | F37: =($C$36-F36)*100 -> 38.712264
A39: Commit floor guard
A40: The maximum permissible discount is set at the point where gross margin reaches the commit floor on the worst single model.
A41: Test | B41: Result
A42: Worst single model, gross margin at card rate | B42: =Rate_Card!$B$46 -> 0.36885246
A43: That model at the maximum commit discount | B43: =1-(1-B42)/(1-Inputs!B50) -> 0.21106557
A44: Commit margin floor | B44: =Inputs!B51 -> 0.15
A45: Headroom in points | B45: =(B43-B44)*100 -> 6.1065574
...

Sheet Sensitivity
A1: Sensitivity
A2: What the partner discount is worth, and what else moves the answer. Every grid recomputes from the class average retail rates on Rate_Card.
A4: How the engine works
A5: Class list at discount d | P5: equals class average retail x (k plus position x (1 minus k)), where k equals (1 minus d) / (1 minus margin floor)
A6: Class cost at discount d | P6: equals class average retail x (1 minus d)
A7: Portfolio | P7: traffic-weighted across the 4 classes
A8: Why list falls as the discount rises | P8: the method is cost-anchored, so a better wholesale price lowers the floor and lowers the customer price at the same time
A10: The discount question
A11: Metric | B11: Value | P11: Note
A12: Discount currently assumed | B12: =Inputs!$B$7 -> 0.45 | P12: Assumption, not a signed term.
A13: Minimum discount for a valid band | B13: =Inputs!$B$6 -> 0.3 | P13: Below the margin floor the floor price exceeds the ceiling and no model can be listed at all.
A14: Portfolio gross margin at that discount | B14: =Rate_Card!$B$45 -> 0.38712264
A15: Worst single model gross margin | B15: =Rate_Card!$B$46 -> 0.36885246 | P15: Tier 1, which carries the majority of traffic.
A16: Worst model at the deepest commit | B16: =Plan_Economics!$B$43 -> 0.21106557 | P16: Tested against the 15% commit floor.
A18: Discount required to reach a target margin
A19: Read off the fine ladder at the bottom of this tab. Target is portfolio gross margin at list.
A20: Target portfolio GM | B20: Required discount | C20: Points above the floor | D20: Card rate at that discount | E20: Gross profit $/1M | F20: Launch-year gross profit | G20: Verdict
A21: 0.3 | B21: =IFERROR(INDEX($B$101:$B$146,MATCH(A21,$F$101:$F$146,1)+1),"Not reachable") -> 0.31 | C21: =IFERROR((B21-Inputs!$B$6)*100,"") -> 1 | D21: =IFERROR(INDEX($D$101:$D$146,MATCH(A21,$F$101:$F$146,1)+1),"") -> 0.64390139 | E21: =IFERROR(INDEX($G$101:$G$146,MATCH(A21,$F$101:$F$146,1)+1),"") -> 0.19654973 | F21: =IFERROR(INDEX($J$101:$J$146,MATCH(A21,$F$101:$F$146,1)+1),"") -> 489495.32 | G21: =IF(NOT(ISNUMBER(B21)),"Out of range",IF(B21<=0.45,"Achievable",IF(B21<=0.55,"Hard ask","Unlikely"))) -> Achievable | P21: The recommended target sits where the verdict is still Achievable and the launch-year gross profit curve has not flattened.
A22: 0.35 | B22: =IFERROR(INDEX($B$101:$B$146,MATCH(A22,$F$101:$F$146,1)+1),"Not reachable") -> 0.4 | C22: =IFERROR((B22-Inputs!$B$6)*100,"") -> 10 | D22: =IFERROR(INDEX($D$101:$D$146,MATCH(A22,$F$101:$F$146,1)+1),"") -> 0.60399229 | E22: =IFERROR(INDEX($G$101:$G$146,MATCH(A22,$F$101:$F$146,1)+1),"") -> 0.21499085 | F22: =IFERROR(INDEX($J$101:$J$146,MATCH(A22,$F$101:$F$146,1)+1),"") -> 541607.16 | G22: =IF(NOT(ISNUMBER(B22)),"Out of range",IF(B22<=0.45,"Achievable",IF(B22<=0.55,"Hard ask","Unlikely"))) -> Achievable
A23: 0.4 | B23: =IFERROR(INDEX($B$101:$B$146,MATCH(A23,$F$101:$F$146,1)+1),"Not reachable") -> 0.47 | C23: =IFERROR((B23-Inputs!$B$6)*100,"") -> 17 | D23: =IFERROR(INDEX($D$101:$D$146,MATCH(A23,$F$101:$F$146,1)+1),"") -> 0.57295187 | E23: =IFERROR(INDEX($G$101:$G$146,MATCH(A23,$F$101:$F$146,1)+1),"") -> 0.22933394 | F23: =IFERROR(INDEX($J$101:$J$146,MATCH(A23,$F$101:$F$146,1)+1),"") -> 582138.59 | G23: =IF(NOT(ISNUMBER(B23)),"Out of range",IF(B23<=0.45,"Achievable",IF(B23<=0.55,"Hard ask","Unlikely"))) -> Hard ask
A24: 0.45 | B24: =IFERROR(INDEX($B$101:$B$146,MATCH(A24,$F$101:$F$146,1)+1),"Not reachable") -> 0.55 | C24: =IFERROR((B24-Inputs!$B$6)*100,"") -> 25 | D24: =IFERROR(INDEX($D$101:$D$146,MATCH(A24,$F$101:$F$146,1)+1),"") -> 0.53747712 | E24: =IFERROR(INDEX($G$101:$G$146,MATCH(A24,$F$101:$F$146,1)+1),"") -> 0.24572604 | F24: =IFERROR(INDEX($J$101:$J$146,MATCH(A24,$F$101:$F$146,1)+1),"") -> 628460.22 | G24: =IF(NOT(ISNUMBER(B24)),"Out of range",IF(B24<=0.45,"Achievable",IF(B24<=0.55,"Hard ask","Unlikely"))) -> Hard ask
A25: 0.5 | B25: =IFERROR(INDEX($B$101:$B$146,MATCH(A25,$F$101:$F$146,1)+1),"Not reachable") -> 0.61 | C25: =IFERROR((B25-Inputs!$B$6)*100,"") -> 31 | D25: =IFERROR(INDEX($D$101:$D$146,MATCH(A25,$F$101:$F$146,1)+1),"") -> 0.51087105 | E25: =IFERROR(INDEX($G$101:$G$146,MATCH(A25,$F$101:$F$146,1)+1),"") -> 0.25802011 | F25: =IFERROR(INDEX($J$101:$J$146,MATCH(A25,$F$101:$F$146,1)+1),"") -> 663201.44 | G25: =IF(NOT(ISNUMBER(B25)),"Out of range",IF(B25<=0.45,"Achievable",IF(B25<=0.55,"Hard ask","Unlikely"))) -> Unlikely
A26: 0.55 | B26: =IFERROR(INDEX($B$101:$B$146,MATCH(A26,$F$101:$F$146,1)+1),"Not reachable") -> 0.67 | C26: =IFERROR((B26-Inputs!$B$6)*100,"") -> 37 | D26: =IFERROR(INDEX($D$101:$D$146,MATCH(A26,$F$101:$F$146,1)+1),"") -> 0.48426498 | E26: =IFERROR(INDEX($G$101:$G$146,MATCH(A26,$F$101:$F$146,1)+1),"") -> 0.27031419 | F26: =IFERROR(INDEX($J$101:$J$146,MATCH(A26,$F$101:$F$146,1)+1),"") -> 697942.67 | G26: =IF(NOT(ISNUMBER(B26)),"Out of range",IF(B26<=0.45,"Achievable",IF(B26<=0.55,"Hard ask","Unlikely"))) -> Unlikely
A29: Discount ladder
A30: Discount | B30: Band exists | C30: Card rate $/1M | D30: Wholesale $/1M | E30: Gross profit $/1M | F30: Portfolio GM | G30: Worst model GM | H30: Commit annual GM | I30: Launch-year revenue | J30: Launch-year gross profit | K30: Launch-year op profit | L30: Breakeven vol 1M/mo | M30: GM gain per 5 pts | N30: GP gain per 5 pts
A31: 0.25 | B31: =IF(A31>Inputs!$B$6,"Yes","NO BAND") -> NO BAND | C31: =Rate_Card!$I$36*Rate_Card!$K$36*(((1-$A31)/(1-Inputs!$B$6))+Rate_Card!$L$36*(1-((1-$A31)/(1-Inputs!$B$6))))+Rate_Card!$I$37*Rate_Card!$K$37*(((1-$A31)/(1-Inputs!$B$6))+Rate_Card!$L$37*(1-((1-$A31)/(1-Inputs!$B$6))))+Rate_Card!$I$38*Rate_Card!$K$38*(((1-$A31)/(1-Inputs!$B$6))+Rate_Card!$L$38*(1-((1-$A31)/(1-Inputs!$B$6))))+Rate_Card!$I$39*Rate_Card!$K$39*(((1-$A31)/(1-Inputs!$B$6))+Rate_Card!$L$39*(1-((1-$A31)/(1-Inputs!$B$6)))) -> 0.67050746 | D31: =Rate_Card!$I$36*Rate_Card!$K$36*(1-$A31)+Rate_Card!$I$37*Rate_Card!$K$37*(1-$A31)+Rate_Card!$I$38*Rate_Card!$K$38*(1-$A31)+Rate_Card!$I$39*Rate_Card!$K$39*(1-$A31) -> 0.4862518 | E31: =C31-D31 -> 0.18425566 | F31: =IF(C31=0,0,E31/C31) -> 0.27480031 | G31: =MIN(1-(1-$A31)/(((1-$A31)/(1-Inputs!$B$6))+Rate_Card!$L$36*(1-((1-$A31)/(1-Inputs!$B$6)))),1-(1-$A31)/(((1-$A31)/(1-Inputs!$B$6))+Rate_Card!$L$37*(1-((1-$A31)/(1-Inputs!$B$6)))),1-(1-$A31)/(((1-$A31)/(1-Inputs!$B$6))+Rate_Card!$L$38*(1-((1-$A31)/(1-Inputs!$B$6)))),1-(1-$A31)/(((1-$A31)/(1-Inputs!$B$6))+Rate_Card!$L$39*(1-((1-$A31)/(1-Inputs!$B$6))))) -> 0.27083333 | H31: =1-D31/(C31*Commit_Annual!$B$27) -> 0.19232903 | I31: =Forecast_12M!$N$11*C31/Rate_Card!$B$42 -> 1763949.1 | J31: =I31-Forecast_12M!$N$5*D31 -> 454754.09 | K31: =J31-Forecast_12M!$N$15 -> -445245.91 | L31: =Inputs!$B$59/(C31*(Forecast_12M!$M$10/Rate_Card!$B$42)-D31) -> 488958.84 | P31: Read the two right-hand columns. They show what each additional 5 points of discount actually buys, and where the return starts to flatten.
A32: 0.3 | B32: =IF(A32>Inputs!$B$6,"Yes","NO BAND") -> NO BAND | C32: =Rate_Card!$I$36*Rate_Card!$K$36*(((1-$A32)/(1-Inputs!$B$6))+Rate_Card!$L$36*(1-((1-$A32)/(1-Inputs!$B$6))))+Rate_Card!$I$37*Rate_Card!$K$37*(((1-$A32)/(1-Inputs!$B$6))+Rate_Card!$L$37*(1-((1-$A32)/(1-Inputs!$B$6))))+Rate_Card!$I$38*Rate_Card!$K$38*(((1-$A32)/(1-Inputs!$B$6))+Rate_Card!$L$38*(1-((1-$A32)/(1-Inputs!$B$6))))+Rate_Card!$I$39*Rate_Card!$K$39*(((1-$A32)/(1-Inputs!$B$6))+Rate_Card!$L$39*(1-((1-$A32)/(1-Inputs!$B$6)))) -> 0.64833573 | D32: =Rate_Card!$I$36*Rate_Card!$K$36*(1-$A32)+Rate_Card!$I$37*Rate_Card!$K$37*(1-$A32)+Rate_Card!$I$38*Rate_Card!$K$38*(1-$A32)+Rate_Card!$I$39*Rate_Card!$K$39*(1-$A32) -> 0.45383501 | E32: =C32-D32 -> 0.19450072 | F32: =IF(C32=0,0,E32/C32) -> 0.3 | G32: =MIN(1-(1-$A32)/(((1-$A32)/(1-Inputs!$B$6))+Rate_Card!$L$36*(1-((1-$A32)/(1-Inputs!$B$6)))),1-(1-$A32)/(((1-$A32)/(1-Inputs!$B$6))+Rate_Card!$L$37*(1-((1-$A32)/(1-Inputs!$B$6)))),1-(1-$A32)/(((1-$A32)/(1-Inputs!$B$6))+Rate_Card!$L$38*(1-((1-$A32)/(1-Inputs!$B$6)))),1-(1-$A32)/(((1-$A32)/(1-Inputs!$B$6))+Rate_Card!$L$39*(1-((1-$A32)/(1-Inputs!$B$6))))) -> 0.3 | H32: =1-D32/(C32*Commit_Annual!$B$27) -> 0.22039448 | I32: =Forecast_12M!$N$11*C32/Rate_Card!$B$42 -> 1705620.4 | J32: =I32-Forecast_12M!$N$5*D32 -> 483705.11 | K32: =J32-Forecast_12M!$N$15 -> -416294.89 | L32: =Inputs!$B$59/(C32*(Forecast_12M!$M$10/Rate_Card!$B$42)-D32) -> 455503.56 | M32: =(F32-F31)*100 -> 2.5199691 | N32: =J32-J31 -> 28951.021
A33: 0.35 | B33: =IF(A33>Inputs!$B$6,"Yes","NO BAND") -> Yes | C33: =Rate_Card!$I$36*Rate_Card!$K$36*(((1-$A33)/(1-Inputs!$B$6))+Rate_Card!$L$36*(1-((1-$A33)/(1-Inputs!$B$6))))+Rate_Card!$I$37*Rate_Card!$K$37*(((1-$A33)/(1-Inputs!$B$6))+Rate_Card!$L$37*(1-((1-$A33)/(1-Inputs!$B$6))))+Rate_Card!$I$38*Rate_Card!$K$38*(((1-$A33)/(1-Inputs!$B$6))+Rate_Card!$L$38*(1-((1-$A33)/(1-Inputs!$B$6))))+Rate_Card!$I$39*Rate_Card!$K$39*(((1-$A33)/(1-Inputs!$B$6))+Rate_Card!$L$39*(1-((1-$A33)/(1-Inputs!$B$6)))) -> 0.62616401 | D33: =Rate_Card!$I$36*Rate_Card!$K$36*(1-$A33)+Rate_Card!$I$37*Rate_Card!$K$37*(1-$A33)+Rate_Card!$I$38*Rate_Card!$K$38*(1-$A33)+Rate_Card!$I$39*Rate_Card!$K$39*(1-$A33) -> 0.42141823 | E33: =C33-D33 -> 0.20474578 | F33: =IF(C33=0,0,E33/C33) -> 0.32698427 | G33: =MIN(1-(1-$A33)/(((1-$A33)/(1-Inputs!$B$6))+Rate_Card!$L$36*(1-((1-$A33)/(1-Inputs!$B$6)))),1-(1-$A33)/(((1-$A33)/(1-Inputs!$B$6))+Rate_Card!$L$37*(1-((1-$A33)/(1-Inputs!$B$6)))),1-(1-$A33)/(((1-$A33)/(1-Inputs!$B$6))+Rate_Card!$L$38*(1-((1-$A33)/(1-Inputs!$B$6)))),1-(1-$A33)/(((1-$A33)/(1-Inputs!$B$6))+Rate_Card!$L$39*(1-((1-$A33)/(1-Inputs!$B$6))))) -> 0.32089552 | H33: =1-D33/(C33*Commit_Annual!$B$27) -> 0.25044746 | I33: =Forecast_12M!$N$11*C33/Rate_Card!$B$42 -> 1647291.8 | J33: =I33-Forecast_12M!$N$5*D33 -> 512656.14 | K33: =J33-Forecast_12M!$N$15 -> -387343.86 | L33: =Inputs!$B$59/(C33*(Forecast_12M!$M$10/Rate_Card!$B$42)-D33) -> 426333.22 | M33: =(F33-F32)*100 -> 2.6984273 | N33: =J33-J32 -> 28951.021
A34: 0.4 | B34: =IF(A34>Inputs!$B$6,"Yes","NO BAND") -> Yes | C34: =Rate_Card!$I$36*Rate_Card!$K$36*(((1-$A34)/(1-Inputs!$B$6))+Rate_Card!$L$36*(1-((1-$A34)/(1-Inputs!$B$6))))+Rate_Card!$I$37*Rate_Card!$K$37*(((1-$A34)/(1-Inputs!$B$6))+Rate_Card!$L$37*(1-((1-$A34)/(1-Inputs!$B$6))))+Rate_Card!$I$38*Rate_Card!$K$38*(((1-$A34)/(1-Inputs!$B$6))+Rate_Card!$L$38*(1-((1-$A34)/(1-Inputs!$B$6))))+Rate_Card!$I$39*Rate_Card!$K$39*(((1-$A34)/(1-Inputs!$B$6))+Rate_Card!$L$39*(1-((1-$A34)/(1-Inputs!$B$6)))) -> 0.60399229 | D34: =Rate_Card!$I$36*Rate_Card!$K$36*(1-$A34)+Rate_Card!$I$37*Rate_Card!$K$37*(1-$A34)+Rate_Card!$I$38*Rate_Card!$K$38*(1-$A34)+Rate_Card!$I$39*Rate_Card!$K$39*(1-$A34) -> 0.38900144 | E34: =C34-D34 -> 0.21499085 | F34: =IF(C34=0,0,E34/C34) -> 0.35594966 | G34: =MIN(1-(1-$A34)/(((1-$A34)/(1-Inputs!$B$6))+Rate_Card!$L$36*(1-((1-$A34)/(1-Inputs!$B$6)))),1-(1-$A34)/(((1-$A34)/(1-Inputs!$B$6))+Rate_Card!$L$37*(1-((1-$A34)/(1-Inputs!$B$6)))),1-(1-$A34)/(((1-$A34)/(1-Inputs!$B$6))+Rate_Card!$L$38*(1-((1-$A34)/(1-Inputs!$B$6)))),1-(1-$A34)/(((1-$A34)/(1-Inputs!$B$6))+Rate_Card!$L$39*(1-((1-$A34)/(1-Inputs!$B$6))))) -> 0.34375 | H34: =1-D34/(C34*Commit_Annual!$B$27) -> 0.28270685 | I34: =Forecast_12M!$N$11*C34/Rate_Card!$B$42 -> 1588963.1 | J34: =I34-Forecast_12M!$N$5*D34 -> 541607.16 | K34: =J34-Forecast_12M!$N$15 -> -358392.84 | L34: =Inputs!$B$59/(C34*(Forecast_12M!$M$10/Rate_Card!$B$42)-D34) -> 400674.14 | M34: =(F34-F33)*100 -> 2.8965384 | N34: =J34-J33 -> 28951.021
A35: 0.45 | B35: =IF(A35>Inputs!$B$6,"Yes","NO BAND") -> Yes | C35: =Rate_Card!$I$36*Rate_Card!$K$36*(((1-$A35)/(1-Inputs!$B$6))+Rate_Card!$L$36*(1-((1-$A35)/(1-Inputs!$B$6))))+Rate_Card!$I$37*Rate_Card!$K$37*(((1-$A35)/(1-Inputs!$B$6))+Rate_Card!$L$37*(1-((1-$A35)/(1-Inputs!$B$6))))+Rate_Card!$I$38*Rate_Card!$K$38*(((1-$A35)/(1-Inputs!$B$6))+Rate_Card!$L$38*(1-((1-$A35)/(1-Inputs!$B$6))))+Rate_Card!$I$39*Rate_Card!$K$39*(((1-$A35)/(1-Inputs!$B$6))+Rate_Card!$L$39*(1-((1-$A35)/(1-Inputs!$B$6)))) -> 0.58182056 | D35: =Rate_Card!$I$36*Rate_Card!$K$36*(1-$A35)+Rate_Card!$I$37*Rate_Card!$K$37*(1-$A35)+Rate_Card!$I$38*Rate_Card!$K$38*(1-$A35)+Rate_Card!$I$39*Rate_Card!$K$39*(1-$A35) -> 0.35658465 | E35: =C35-D35 -> 0.22523591 | F35: =IF(C35=0,0,E35/C35) -> 0.38712264 | G35: =MIN(1-(1-$A35)/(((1-$A35)/(1-Inputs!$B$6))+Rate_Card!$L$36*(1-((1-$A35)/(1-Inputs!$B$6)))),1-(1-$A35)/(((1-$A35)/(1-Inputs!$B$6))+Rate_Card!$L$37*(1-((1-$A35)/(1-Inputs!$B$6)))),1-(1-$A35)/(((1-$A35)/(1-Inputs!$B$6))+Rate_Card!$L$38*(1-((1-$A35)/(1-Inputs!$B$6)))),1-(1-$A35)/(((1-$A35)/(1-Inputs!$B$6))+Rate_Card!$L$39*(1-((1-$A35)/(1-Inputs!$B$6))))) -> 0.36885246 | H35: =1-D35/(C35*Commit_Annual!$B$27) -> 0.31742489 | I35: =Forecast_12M!$N$11*C35/Rate_Card!$B$42 -> 1530634.5 | J35: =I35-Forecast_12M!$N$5*D35 -> 570558.18 | K35: =J35-Forecast_12M!$N$15 -> -329441.82 | L35: =Inputs!$B$59/(C35*(Forecast_12M!$M$10/Rate_Card!$B$42)-D35) -> 377928.33 | M35: =(F35-F34)*100 -> 3.117298 | N35: =J35-J34 -> 28951.021
A36: 0.5 | B36: =IF(A36>Inputs!$B$6,"Yes","NO BAND") -> Yes | C36: =Rate_Card!$I$36*Rate_Card!$K$36*(((1-$A36)/(1-Inputs!$B$6))+Rate_Card!$L$36*(1-((1-$A36)/(1-Inputs!$B$6))))+Rate_Card!$I$37*Rate_Card!$K$37*(((1-$A36)/(1-Inputs!$B$6))+Rate_Card!$L$37*(1-((1-$A36)/(1-Inputs!$B$6))))+Rate_Card!$I$38*Rate_Card!$K$38*(((1-$A36)/(1-Inputs!$B$6))+Rate_Card!$L$38*(1-((1-$A36)/(1-Inputs!$B$6))))+Rate_Card!$I$39*Rate_Card!$K$39*(((1-$A36)/(1-Inputs!$B$6))+Rate_Card!$L$39*(1-((1-$A36)/(1-Inputs!$B$6)))) -> 0.55964884 | D36: =Rate_Card!$I$36*Rate_Card!$K$36*(1-$A36)+Rate_Card!$I$37*Rate_Card!$K$37*(1-$A36)+Rate_Card!$I$38*Rate_Card!$K$38*(1-$A36)+Rate_Card!$I$39*Rate_Card!$K$39*(1-$A36) -> 0.32416787 | E36: =C36-D36 -> 0.23548097 | F36: =IF(C36=0,0,E36/C36) -> 0.42076559 | G36: =MIN(1-(1-$A36)/(((1-$A36)/(1-Inputs!$B$6))+Rate_Card!$L$36*(1-((1-$A36)/(1-Inputs!$B$6)))),1-(1-$A36)/(((1-$A36)/(1-Inputs!$B$6))+Rate_Card!$L$37*(1-((1-$A36)/(1-Inputs!$B$6)))),1-(1-$A36)/(((1-$A36)/(1-Inputs!$B$6))+Rate_Card!$L$38*(1-((1-$A36)/(1-Inputs!$B$6)))),1-(1-$A36)/(((1-$A36)/(1-Inputs!$B$6))+Rate_Card!$L$39*(1-((1-$A36)/(1-Inputs!$B$6))))) -> 0.39655172 | H36: =1-D36/(C36*Commit_Annual!$B$27) -> 0.35489379 | I36: =Forecast_12M!$N$11*C36/Rate_Card!$B$42 -> 1472305.8 | J36: =I36-Forecast_12M!$N$5*D36 -> 599509.2 | K36: =J36-Forecast_12M!$N$15 -> -300490.8 | L36: =Inputs!$B$59/(C36*(Forecast_12M!$M$10/Rate_Card!$B$42)-D36) -> 357626.3 | M36: =(F36-F35)*100 -> 3.3642953 | N36: =J36-J35 -> 28951.021
A37: 0.55 | B37: =IF(A37>Inputs!$B$6,"Yes","NO BAND") -> Yes | C37: =Rate_Card!$I$36*Rate_Card!$K$36*(((1-$A37)/(1-Inputs!$B$6))+Rate_Card!$L$36*(1-((1-$A37)/(1-Inputs!$B$6))))+Rate_Card!$I$37*Rate_Card!$K$37*(((1-$A37)/(1-Inputs!$B$6))+Rate_Card!$L$37*(1-((1-$A37)/(1-Inputs!$B$6))))+Rate_Card!$I$38*Rate_Card!$K$38*(((1-$A37)/(1-Inputs!$B$6))+Rate_Card!$L$38*(1-((1-$A37)/(1-Inputs!$B$6))))+Rate_Card!$I$39*Rate_Card!$K$39*(((1-$A37)/(1-Inputs!$B$6))+Rate_Card!$L$39*(1-((1-$A37)/(1-Inputs!$B$6)))) -> 0.53747712 | D37: =Rate_Card!$I$36*Rate_Card!$K$36*(1-$A37)+Rate_Card!$I$37*Rate_Card!$K$37*(1-$A37)+Rate_Card!$I$38*Rate_Card!$K$38*(1-$A37)+Rate_Card!$I$39*Rate_Card!$K$39*(1-$A37) -> 0.29175108 | E37: =C37-D37 -> 0.24572604 | F37: =IF(C37=0,0,E37/C37) -> 0.45718418 | G37: =MIN(1-(1-$A37)/(((1-$A37)/(1-Inputs!$B$6))+Rate_Card!$L$36*(1-((1-$A37)/(1-Inputs!$B$6)))),1-(1-$A37)/(((1-$A37)/(1-Inputs!$B$6))+Rate_Card!$L$37*(1-((1-$A37)/(1-Inputs!$B$6)))),1-(1-$A37)/(((1-$A37)/(1-Inputs!$B$6))+Rate_Card!$L$38*(1-((1-$A37)/(1-Inputs!$B$6)))),1-(1-$A37)/(((1-$A37)/(1-Inputs!$B$6))+Rate_Card!$L$39*(1-((1-$A37)/(1-Inputs!$B$6))))) -> 0.42727273 | H37: =1-D37/(C37*Commit_Annual!$B$27) -> 0.39545399 | I37: =Forecast_12M!$N$11*C37/Rate_Card!$B$42 -> 1413977.2 | J37: =I37-Forecast_12M!$N$5*D37 -> 628460.22 | K37: =J37-Forecast_12M!$N$15 -> -271539.78 | L37: =Inputs!$B$59/(C37*(Forecast_12M!$M$10/Rate_Card!$B$42)-D37) -> 339394.29 | M37: =(F37-F36)*100 -> 3.6418595 | N37: =J37-J36 -> 28951.021
A38: 0.6 | B38: =IF(A38>Inputs!$B$6,"Yes","NO BAND") -> Yes | C38: =Rate_Card!$I$36*Rate_Card!$K$36*(((1-$A38)/(1-Inputs!$B$6))+Rate_Card!$L$36*(1-((1-$A38)/(1-Inputs!$B$6))))+Rate_Card!$I$37*Rate_Card!$K$37*(((1-$A38)/(1-Inputs!$B$6))+Rate_Card!$L$37*(1-((1-$A38)/(1-Inputs!$B$6))))+Rate_Card!$I$38*Rate_Card!$K$38*(((1-$A38)/(1-Inputs!$B$6))+Rate_Card!$L$38*(1-((1-$A38)/(1-Inputs!$B$6))))+Rate_Card!$I$39*Rate_Card!$K$39*(((1-$A38)/(1-Inputs!$B$6))+Rate_Card!$L$39*(1-((1-$A38)/(1-Inputs!$B$6)))) -> 0.51530539 | D38: =Rate_Card!$I$36*Rate_Card!$K$36*(1-$A38)+Rate_Card!$I$37*Rate_Card!$K$37*(1-$A38)+Rate_Card!$I$38*Rate_Card!$K$38*(1-$A38)+Rate_Card!$I$39*Rate_Card!$K$39*(1-$A38) -> 0.25933429 | E38: =C38-D38 -> 0.2559711 | F38: =IF(C38=0,0,E38/C38) -> 0.4967367 | G38: =MIN(1-(1-$A38)/(((1-$A38)/(1-Inputs!$B$6))+Rate_Card!$L$36*(1-((1-$A38)/(1-Inputs!$B$6)))),1-(1-$A38)/(((1-$A38)/(1-Inputs!$B$6))+Rate_Card!$L$37*(1-((1-$A38)/(1-Inputs!$B$6)))),1-(1-$A38)/(((1-$A38)/(1-Inputs!$B$6))+Rate_Card!$L$38*(1-((1-$A38)/(1-Inputs!$B$6)))),1-(1-$A38)/(((1-$A38)/(1-Inputs!$B$6))+Rate_Card!$L$39*(1-((1-$A38)/(1-Inputs!$B$6))))) -> 0.46153846 | H38: =1-D38/(C38*Commit_Annual!$B$27) -> 0.4395045 | I38: =Forecast_12M!$N$11*C38/Rate_Card!$B$42 -> 1355648.6 | J38: =I38-Forecast_12M!$N$5*D38 -> 657411.24 | K38: =J38-Forecast_12M!$N$15 -> -242588.76 | L38: =Inputs!$B$59/(C38*(Forecast_12M!$M$10/Rate_Card!$B$42)-D38) -> 322931.07 | M38: =(F38-F37)*100 -> 3.9552516 | N38: =J38-J37 -> 28951.021
A39: 0.65 | B39: =IF(A39>Inputs!$B$6,"Yes","NO BAND") -> Yes | C39: =Rate_Card!$I$36*Rate_Card!$K$36*(((1-$A39)/(1-Inputs!$B$6))+Rate_Card!$L$36*(1-((1-$A39)/(1-Inputs!$B$6))))+Rate_Card!$I$37*Rate_Card!$K$37*(((1-$A39)/(1-Inputs!$B$6))+Rate_Card!$L$37*(1-((1-$A39)/(1-Inputs!$B$6))))+Rate_Card!$I$38*Rate_Card!$K$38*(((1-$A39)/(1-Inputs!$B$6))+Rate_Card!$L$38*(1-((1-$A39)/(1-Inputs!$B$6))))+Rate_Card!$I$39*Rate_Card!$K$39*(((1-$A39)/(1-Inputs!$B$6))+Rate_Card!$L$39*(1-((1-$A39)/(1-Inputs!$B$6)))) -> 0.49313367 | D39: =Rate_Card!$I$36*Rate_Card!$K$36*(1-$A39)+Rate_Card!$I$37*Rate_Card!$K$37*(1-$A39)+Rate_Card!$I$38*Rate_Card!$K$38*(1-$A39)+Rate_Card!$I$39*Rate_Card!$K$39*(1-$A39) -> 0.22691751 | E39: =C39-D39 -> 0.26621616 | F39: =IF(C39=0,0,E39/C39) -> 0.53984585 | G39: =MIN(1-(1-$A39)/(((1-$A39)/(1-Inputs!$B$6))+Rate_Card!$L$36*(1-((1-$A39)/(1-Inputs!$B$6)))),1-(1-$A39)/(((1-$A39)/(1-Inputs!$B$6))+Rate_Card!$L$37*(1-((1-$A39)/(1-Inputs!$B$6)))),1-(1-$A39)/(((1-$A39)/(1-Inputs!$B$6))+Rate_Card!$L$38*(1-((1-$A39)/(1-Inputs!$B$6)))),1-(1-$A39)/(((1-$A39)/(1-Inputs!$B$6))+Rate_Card!$L$39*(1-((1-$A39)/(1-Inputs!$B$6))))) -> 0.5 | H39: =1-D39/(C39*Commit_Annual!$B$27) -> 0.48751612 | I39: =Forecast_12M!$N$11*C39/Rate_Card!$B$42 -> 1297319.9 | J39: =I39-Forecast_12M!$N$5*D39 -> 686362.26 | K39: =J39-Forecast_12M!$N$15 -> -213637.74 | L39: =Inputs!$B$59/(C39*(Forecast_12M!$M$10/Rate_Card!$B$42)-D39) -> 307991.13 | M39: =(F39-F38)*100 -> 4.3109147 | N39: =J39-J38 -> 28951.021
A42: Portfolio gross margin, discount against list positioning
A43: Positioning shift moves every class position score up or down together. Higher means listing closer to the ceiling, which is the arbitrage limit.
A44: Discount | B44: -0.2 | C44: -0.1 | D44: 0 | E44: 0.1 | F44: 0.2
